Workbook

Sheet Oku
B1: 4. oturum: Excel II, kredi ve karar araçları
B3: Bu dosyayı nasıl kullanırım?
B4: Haftanın vakası: TCMB'ye göre ihtiyaç kredisi faizi yıllık %63 (4 Eylül 2026 haftası; PPK toplantı özeti, 17.09.2026). İlandaki 'aylık %3,89'dan başlayan faiz' bu ortalamanın neresindedir; 100.000 TL için üç teklifin hangisinin maliyeti en düşüktür, hangisinin taksiti bütçeye sığar?
B5: Teklifler, gelir ve bütçe eşiği varsayımsaldır; piyasa verisi değildir. Vergiler (KKDF, BSMV) modele dahil değildir. Kredi tavsiyesi değildir.
B6: Sayfalar: Finans (finans temeli, el kitabı f03), Girdiler (Hesap ve Cikti sayfalarının varsayımları), Hesap (çalışılmış örnekler: FV, PV, kredi ve amortisman, NPV ve IRR, yani net bugünkü değer ve iç verim oranı), Cikti (özet), Karar (TCMB oranının hesabı, Goal Seek, Data Table, IF, AND, OR), Uygulama (derste: G1, G2, G4), Ileri (isteğe bağlı), Ev (notsuz).
B7: Finans sayfası el kitabının f03 bölümüyle birlikte okunur: finans-temeli/f03-paranin-zaman-degeri-ve-kredi.md. Girdileri kendi içindedir.
B8: Hesap ve Cikti'deki bir varsayım yalnız Girdiler sayfasında değiştirilir. Sayfalar arası başvuru: =Girdiler!B5, 'Girdiler sayfasındaki B5 hücresi' demektir; bu hücreler yeşil yazılır.
B9: Goal Seek ve Data Table masaüstü Excel'de çalışır (Data > What-If Analysis). Web için Excel'de yoktur.
B10: Çalışma sırası: el kitabı f03, ders notu, Finans, Hesap, Karar, Uygulama, Ileri, Ev, Colab defteri.
B11: Etiketler: [G] Girdiler, [D] Dönem ve oran, [İ] İşaret, [H] Hesap, [S] Sağlama, [Y] Yorum.
B12: İşaret kuralı: borçludan çıkan para eksi, borçluya giren para artı. Excel'in finans fonksiyonları bu kurala göre çalışır.
B13: Fark hücreleri 0,000000 göstermelidir. Çok küçük bir eksi sayı -0,000000 gibi görünebilir; bu da sıfırdır.
... B25: Ondalık işareti ve formüldeki ayırıcı bilgisayarın bölge ayarından gelir (Türkçe bölge ayarında 0,4 ve ;). Dosya her dilde ve bölge ayarında aynı çalışır.

Sheet Finans
A1: Finans temeli (f03): paranın zaman değeri ve kredinin maliyeti
A2: El kitabı bölümü: finans-temeli/f03-paranin-zaman-degeri-ve-kredi.md. Bu sayfa teorinin 5-25. dakikasındaki Finans temeli bloğunun Excel yazımıdır.
A3: Girdiler (mavi) bu sayfada durur; Girdiler sayfasına bağlı değildir. Oranlar öğretim amaçlı varsayımdır, piyasa verisi değildir.
A5: F1. İskonto: gelecekteki parayı bugüne taşımak
A6: [G] Gelecekteki tutar | B6: 27440
A7: [G] Yıllık oran | B7: 0.4
A8: [G] Süre (yıl) | B8: 3
A9: [D] Dönem | C9: Oran yıllık, süre yıl: birimler uyumlu.
A10: [H] İskonto çarpanı | B10: =1/(1+B7)^B8 | C10: 1 / (1 + oran) ^ dönem: gelecekteki 1 TL'nin bugünkü değeri.
A11: [H] Bugünkü değer | B11: =B6*B10 | C11: Gelecekteki tutar × iskonto çarpanı. Tek formülle: =B6/(1+B7)^B8
A12: [S] Sağlama: PV fonksiyonuyla | B12: =-PV(B7,B8,0,B6) | C12: Formül: =-PV(B7,B8,0,B6). PV tek başına eksi verir (bugün cepten çıkan); başına eksi konur. Hesap!B34 aynı hesabı eksi işaretle gösterir.
A13: [S] Fark | B13: =B11-B12
A14: [Y] Yorum | C14: Para yıllık bu oranla değerlendirilebilirse gelecekteki tutar bugünkü değere denktir. Oran büyüdükçe bugünkü değer küçülür.
A16: F2. Eşit taksitli kredi ve toplam faiz
A17: [G] Kredi tutarı | B17: 100000
A18: [G] Aylık faiz oranı | B18: 0.03
A19: [G] Vade (ay) | B19: 12
A20: [D] Dönem | C20: Oran aylık, taksit aylık, vade ay: birimler uyumlu.
A21: [İ] İşaret | C21: Kredi borçluya gelir (artı), taksit borçludan çıkar (eksi). PMT eksi verir; başına eksi konur.
A22: [H] Aylık taksit | B22: =-PMT(B18,B19,B17) | C22: Formül: =-PMT(B18,B19,B17)
A23: [H] Toplam ödeme | B23: =B22*B19 | C23: Taksit × vade
A24: [H] Toplam faiz | B24: =B23-B17 | C24: Toplam ödeme - kredi tutarı. Kredinin borçluya maliyeti budur; toplam ödemenin geri kalanı borcun iadesidir.
A25: [H] 1. ay faizi | B25: =B17*B18 | C25: İlk ay faiz bütün borç üzerinden işler.
A26: [H] 1. ay anapara | B26: =B22-B25 | C26: Taksit - faiz. Borç azaldıkça faiz payı azalır, anapara payı artar (Hesap sayfasındaki amortisman tablosu).
A27: [S] Sağlama: kapalı formülle taksit - B22 | B27: =B17*B18/(1-(1+B18)^(-B19))-B22 | C27: Kapalı formül: taksit = kredi * oran / (1 - (1 + oran) ^ (-vade)); bu hücrede =B17*B18/(1-(1+B18)^(-B19))-B22 (el kitabı f03, 2.3; İleri 1). 0 çıkmalı: iki yol aynı taksiti verir.
A28: [Y] Sık hata: kredi × oran × vade | B28: =B17*B18*B19 | C28: Yanlış tahmin: faizin bütün vade boyunca ilk borç üzerinden işlediğini varsayar.
A29: [Y] Sık hata - gerçek toplam faiz | B29: =B28-B24 | C29: Fark büyük, çünkü faiz her ay azalan kalan borca işler.
A30: F3. Aylık oranın yıllık karşılığı: nominal ve etkin
A31: [G] Aylık oran | B31: 0.03
A32: [G] Yıldaki ay sayısı | B32: 12
A33: [H] Yıllık nominal oran | B33: =B31*B32 | C33: Aylık oran × yıldaki ay sayısı. Faizin faize işlemesini hesaba katmaz.
A34: [H] Yıllık etkin oran | B34: =(1+B31)^B32-1 | C34: (1 + aylık oran) ^ ay sayısı - 1: para bir yılda gerçekte bu kadar büyür (H2'deki bileşik faiz).
A35: [S] Sağlama: EFFECT | B35: =EFFECT(B33,B32) | C35: Formül: =EFFECT(B33,B32)
A36: [S] Fark | B36: =B34-B35
A37: [Y] Yorum | C37: Bir oran görüldüğünde sorulacaklar: aylık mı yıllık mı, nominal mi etkin mi? Efektif yıllık faiz oranı (EYFO) başka bir sayıdır: vergi ve ücretleri de içerir (F4).
A39: F4. Kredinin maliyetine neler girer? (yalnız okuma)
A40: Akdi faiz: sözleşmede yazan faiz oranı. F2'deki aylık oran budur.
A41: KKDF (Kaynak Kullanımını Destekleme Fonu) kesintisi: tüketici kredisinde %15, faiz tutarı üzerinden alınır.
A42: BSMV (Banka ve Sigorta Muameleleri Vergisi): tüketici kredisinde %15, bankanın lehine aldığı paralar üzerinden alınır; bunların başlıcası faizdir. Anapara üzerinden ikisi de alınmaz.
A43: Tahsis ücreti: tüketici kredisinde kullandırılan anaparanın binde beşini geçemez (100.000 TL'de en çok 500 TL).
...

Sheet Girdiler
A1: Girdiler: Hesap ve Cikti sayfalarının bütün varsayımları bu sayfada
A2: Mavi hücreler değiştirilebilir. Hesap ve Cikti sayfaları kendiliğinden güncellenir. Bu sayfada formül yok.
A4: Örnek 1: düzenli birikim
A5: Aylık faiz oranı | B5: 0.03 | C5: Her ay bakiyeye işleyen faiz. %3 ile 0,03 aynı sayıdır.
A6: Dönem sayısı (ay) | B6: 12 | C6: Kaç ay para yatırılacağı.
A7: Her ay yatırılan tutar | B7: 1000 | C7: Her ayın sonunda yatırılır. Burada artı yazılır; işaret Hesap sayfasında verilir.
A9: Örnek 1b: tersine hesap (H2'deki bileşik faiz)
A10: Hedef tutar (süre sonunda) | B10: 27440 | C10: H2'de bulunan sonuç. Soru: bunun için bugün ne yatırılmalı?
A11: Yıllık faiz oranı | B11: 0.4
A12: Süre (yıl) | B12: 3
A14: Örnek 2: kredi
A15: Kredi tutarı | B15: 100000 | C15: Bankadan bugün alınan para.
A16: Aylık faiz oranı | B16: 0.03 | C16: Öğretim amaçlı varsayım; bir bankanın gerçek teklifi değildir.
A17: Vade (ay) | B17: 12
A19: Örnek 3: proje (NPV ve IRR)
A20: İstenen getiri (yıllık iskonto oranı) | B20: 0.1 | C20: Bu projeye para bağlamak için istenen en düşük yıllık getiri.
A21: Ne zaman? | B21: Nakit akışı
A22: Dönem 0 (bugün): yatırım | B22: -10000 | C22: Cepten çıkan: eksi.
A23: Dönem 1 sonu: giriş | B23: 3000 | C23: Cebe giren: artı.
A24: Dönem 2 sonu: giriş | B24: 4200
A25: Dönem 3 sonu: giriş | B25: 6800
A27: Öğretim için seçilmiş örnek değerler; gerçek bir proje ya da banka teklifi değildir. Bir dönem burada bir yıldır.

Sheet Hesap
A1: Hesap: çalışılmış örnekler
A2: Yeşil hücreler değeri Girdiler sayfasından çeker. Siyah hücreler bu sayfanın hesaplarıdır. Formül, hücreye tıklanınca formül çubuğunda görünür.
A4: Örnek 1: düzenli birikim (FV)
A5: [G] Aylık faiz oranı | B5: =Girdiler!B5 | C5: Bu hücrede =Girdiler!B5 yazar: 'Girdiler sayfasının B5 hücresini getir' demektir. Yeşil yazı bunu gösterir.
A6: [G] Dönem sayısı (ay) | B6: =Girdiler!B6
A7: [G] Her ay yatırılan tutar | B7: =Girdiler!B7
A8: [D] Oran ve dönem aynı birimde mi? | C8: Evet: aylık oran, aylık dönem, aylık katkı. Biri yıllık olsaydı önce aynı birime çevrilirdi.
A9: [İ] İşaret | C9: Yatırılan para cepten çıkar: formülde -B7 yazılır. Sonuç artı çıkar: süre sonunda geri dönen para.
A10: [H] Dönem sonunda birikim | B10: =FV(B5,B6,-B7) | C10: Formül: =FV(B5,B6,-B7)
A11: [İ] Deneme: katkı artı verilirse | B11: =FV(B5,B6,B7) | C11: Formül: =FV(B5,B6,B7). Aynı sayı, eksi işaretle: Excel sonucu ödenecek para olarak okur.
A12: FV'nin içini görmek için aynı hesabı ay ay yapan tablo. H6'da aynı hesap Python döngüsüyle yazılır.
A13: Ay | B13: Dönem başı bakiye | C13: Faiz | D13: Katkı | E13: Dönem sonu bakiye
A14: 0 | E14: 0 | F14: Ay 0 = bugün. Gri 0'lar yapısaldır: hesap boş başlar (FV'de 4. argümanın boş bırakılması da bunu söyler).
A15: =A14+1 | B15: =E14 | C15: =B15*$B$5 | D15: =$B$7 | E15: =B15+C15+D15 | F15: Faiz: =B15*$B$5 Katkı: =$B$7 Dönem sonu: =B15+C15+D15
A16: =A15+1 | B16: =E15 | C16: =B16*$B$5 | D16: =$B$7 | E16: =B16+C16+D16
A17: =A16+1 | B17: =E16 | C17: =B17*$B$5 | D17: =$B$7 | E17: =B17+C17+D17
A18: =A17+1 | B18: =E17 | C18: =B18*$B$5 | D18: =$B$7 | E18: =B18+C18+D18
A19: =A18+1 | B19: =E18 | C19: =B19*$B$5 | D19: =$B$7 | E19: =B19+C19+D19
A20: =A19+1 | B20: =E19 | C20: =B20*$B$5 | D20: =$B$7 | E20: =B20+C20+D20
A21: =A20+1 | B21: =E20 | C21: =B21*$B$5 | D21: =$B$7 | E21: =B21+C21+D21
A22: =A21+1 | B22: =E21 | C22: =B22*$B$5 | D22: =$B$7 | E22: =B22+C22+D22
A23: =A22+1 | B23: =E22 | C23: =B23*$B$5 | D23: =$B$7 | E23: =B23+C23+D23
A24: =A23+1 | B24: =E23 | C24: =B24*$B$5 | D24: =$B$7 | E24: =B24+C24+D24
A25: =A24+1 | B25: =E24 | C25: =B25*$B$5 | D25: =$B$7 | E25: =B25+C25+D25
A26: =A25+1 | B26: =E25 | C26: =B26*$B$5 | D26: =$B$7 | E26: =B26+C26+D26
A28: [S] Sağlama: tablonun son bakiyesi - FV | B28: =E26-B10 | C28: 0 çıkmalı: iki farklı yol aynı sonucu verir.
A30: Örnek 1b: tersine hesap (PV)
A31: [G] Hedef tutar (süre sonunda) | B31: =Girdiler!B10
A32: [G] Yıllık faiz oranı | B32: =Girdiler!B11 | C32: [D] Oran yıllık, süre yıl: birimler uyumlu.
A33: [G] Süre (yıl) | B33: =Girdiler!B12
A34: [H] Bugün yatırılması gereken | B34: =PV(B32,B33,0,B31) | C34: Formül: =PV(B32,B33,0,B31). 0: arada düzenli ödeme yok. [İ] Sonuç eksi: bugün cepten çıkan para.
A35: [S] Sağlama: H2 formülüyle ileri taşı | B35: =-B34*(1+B32)^B33 | C35: H2'deki =B1*(1+B2)^B3 kalıbı. Baştaki eksi, eksi tutarı artıya çevirir.
A36: [S] Fark | B36: =B35-B31
A38: Örnek 2: kredi taksiti ve amortisman tablosu
A39: [G] Kredi tutarı | B39: =Girdiler!B15
A40: [G] Aylık faiz oranı | B40: =Girdiler!B16
A41: [G] Vade (ay) | B41: =Girdiler!B17 | C41: [D] Oran aylık, vade ay: birimler uyumlu.
A42: [İ] İşaret | C42: Kredi borçluya gelen para (artı). PMT taksiti eksi verir; başına eksi konarak taksit artı gösterilir.
A43: [H] Aylık taksit | B43: =-PMT(B40,B41,B39) | C43: Formül: =-PMT(B40,B41,B39)
A45: Amortisman tablosu: her taksitin ne kadarı faize, ne kadarı borca gider? $ işaretli başvurular sürüklerken sabit kalır.
...

Sheet Cikti
A1: Çıktı: karar için özet
A2: Bu sayfada hesap yok. Bütün hücreler Hesap sayfasına bağlı (yeşil). Girdiler'de bir sayı değişince burası da değişir.
A4: Kredi (Örnek 2)
A5: Kredi tutarı | B5: =Hesap!B39
A6: Aylık taksit | B6: =Hesap!B43 | C6: Formül: =Hesap!B43
A7: Toplam ödeme | B7: =Hesap!B64
A8: Toplam faiz | B8: =Hesap!B65
A10: Birikim (Örnek 1)
A11: Dönem sonunda birikim | B11: =Hesap!B10
A12: Hedef tutar için bugün yatırılacak | B12: =-Hesap!B34 | C12: Formül: =-Hesap!B34. Hesap'taki sonuç eksi (cepten çıkan); özette tutar olarak artı gösterilir.
A14: Proje (Örnek 3)
A15: İstenen getiri | B15: =Hesap!B69
A16: Net bugünkü değer (NPV) | B16: =Hesap!B78
A17: İç verim oranı (IRR) | B17: =Hesap!B85
A18: Karar | B18: =Hesap!B88 | C18: NPV kuralına göre karar (NPV > 0 ise Kabul). IRR kuralının kararı Hesap!B89'da.

Sheet Karar
A1: Karar araçları: TCMB'nin kredi faizi, Goal Seek, Data Table, IF, AND, OR
A2: Çalışılmış örnekler. Goal Seek ve Data Table masaüstü Excel'de çalışır; Web için Excel'de yoktur.
A5: K1 TCMB'nin %63'ü nasıl hesaplanır? Metaverideki örnek
A6: [G] Kredi tutarı (TL) | B6: 10000
A7: [G] Aylık ödeme (TL) | B7: 480
A8: [G] Vade (ay) | B8: 24
A9: [G] TCMB ihtiyaç kredisi faizi (4 Eylül 2026 haftası) | B9: 0.63
A10: [G] Yılda ay sayısı | B10: 12
A11: Birim çevirme: yüzde puan = oran × 100 | B11: 100
A13: Ay | B13: Ödeme tarihi | C13: Nakit akışı (TL)
A14: 0 | B14: 40909 | C14: =B6 | D14: Ay 0: kredi borçluya gelir (artı). Ay 1-24: ödeme borçludan çıkar (eksi).
A15: =A14+1 | B15: 40940 | C15: =-$B$7
A16: =A15+1 | B16: 40969 | C16: =-$B$7
A17: =A16+1 | B17: 41000 | C17: =-$B$7
A18: =A17+1 | B18: 41030 | C18: =-$B$7
A19: =A18+1 | B19: 41061 | C19: =-$B$7
A20: =A19+1 | B20: 41091 | C20: =-$B$7
A21: =A20+1 | B21: 41122 | C21: =-$B$7
A22: =A21+1 | B22: 41153 | C22: =-$B$7
A23: =A22+1 | B23: 41183 | C23: =-$B$7
A24: =A23+1 | B24: 41214 | C24: =-$B$7
A25: =A24+1 | B25: 41244 | C25: =-$B$7
A26: =A25+1 | B26: 41275 | C26: =-$B$7
... A38: =A37+1 | B38: 41640 | C38: =-$B$7
A40: [H] Aylık iç verim oranı | B40: =IRR(C14:C38) | C40: Formül: =IRR(C14:C38)
A41: [H] Yıllık bileşik karşılığı | B41: =(1+B40)^B10-1 | C41: (1 + aylık)^12 - 1. Metaverideki sonuç: %14,90.
A42: [H] Tarihli akışla yıllık oran | B42: =XIRR(C14:C38,B14:B38) | C42: Formül: =XIRR(C14:C38,B14:B38). Gün sayısı / 365 ile iskonto eder; TCMB'nin formülüyle aynı.
A43: [H] İki yolun farkı (yüzde puan) | B43: =(B41-B42)*B11 | C43: Aylar eşit uzunlukta değildir (28-31 gün); fark bu yüzdendir ve küçüktür.
A44: [H] %63'ün aylık bileşik karşılığı | B44: =(1+B9)^(1/B10)-1
A45: [H] Yanlış okuma: %63 / 12 | B45: =B9/B10 | C45: Yıllık bileşik oran 12'ye bölünmez; bölme yalnız yıllık nominal orandan aylık orana geçişte kullanılır.
A47: K2 İlan kredisi: taksit, yıllık karşılık ve Goal Seek
A48: [G] Kredi tutarı (TL) | B48: 100000
A49: [G] Aylık akdi faiz oranı | B49: 0.04
A50: [G] Vade (ay) | B50: 12
A51: [G] Aylık net gelir (TL) | B51: 24000
A52: [G] Bütçe eşiği: taksit / gelir en çok | B52: 0.4
A53: [G] Ödenebilecek en yüksek taksit (TL) | B53: 7500
A54: [G] Vade üst sınırı (ay) | B54: 24
A56: [H] Aylık taksit | B56: =-PMT(B49,B50,B48) | C56: Formül: =-PMT(B49,B50,B48)
A57: [H] Toplam faiz | B57: =B56*B50-B48
...

Sheet Uygulama
A1: Uygulama (derste, 50 dakika): üç kredi teklifi
A2: Sarı hücreler öğrenci tarafından doldurulur. Formüle sayı yazılmaz; her sayı mavi bir girdi hücresindedir. Teklifler varsayımsaldır; vergiler (KKDF, BSMV) modele dahil değildir.
A3: Süre: G1 12 dk, G2 12 dk, G4 Excel kısmı (bu sayfa); G3 12 dk ve G4'ün Python kısmı Colab defterinde. Kredi tavsiyesi değildir.
A5: G1 (12 dk): üç teklifin taksiti, toplam faizi ve amortisman tablosu
A6: [G] Kredi tutarı (TL) | B6: 100000
A7: [G] Aylık net gelir (TL) | B7: 24000
A8: [G] Bütçe eşiği: taksit / gelir en çok | B8: 0.4
A9: [G] TCMB ihtiyaç kredisi faizi (4 Eylül 2026 haftası) | B9: 0.63
A10: [G] Yılda ay sayısı | B10: 12
A11: Birim çevirme: yüzde puan = oran × 100 | B11: 100
A12: Teklif | B12: Aylık akdi oran | C12: Vade (ay) | D12: Tahsis ücreti (TL) | E12: Aylık taksit | F12: Toplam ödeme | G12: Toplam faiz | H12: Taksit / gelir
A13: A | B13: 0.0399 | C13: 12 | D13: 500
A14: B | B14: 0.0405 | C14: 12 | D14: 0
A15: C | B15: 0.0389 | C15: 24 | D15: 500
A16: Tahmin sorusu (hesaptan önce): akdi oranı en düşük teklif, en düşük toplam faizi ve en düşük maliyeti de verir mi?
A18: G1 (devam): üç amortisman tablosu
A19: Önce Teklif A bloğu kurulur. Blok (A21:E47) kopyalanıp G21 ve M21'e yapıştırılır; karma başvurular (B$21, D$21) her bloğun kendi oranını ve taksitini bulur. A ve B'de 12, C'de 24 satır doldurulur.
A20: Teklif A | G20: Teklif B | M20: Teklif C
A21: Oran | C21: Taksit | G21: Oran | I21: Taksit | M21: Oran | O21: Taksit
A22: Ay | B22: Başlangıç borcu | C22: Faiz | D22: Anapara | E22: Kalan borç | G22: Ay | H22: Başlangıç borcu | I22: Faiz | J22: Anapara | K22: Kalan borç | M22: Ay | N22: Başlangıç borcu | O22: Faiz | P22: Anapara | Q22: Kalan borç
A23: 0 | E23: =$B$6 | G23: 0 | K23: =$B$6 | M23: 0 | Q23: =$B$6
A24: =A23+1 | G24: =G23+1 | M24: =M23+1
A25: =A24+1 | G25: =G24+1 | M25: =M24+1
A26: =A25+1 | G26: =G25+1 | M26: =M25+1
A27: =A26+1 | G27: =G26+1 | M27: =M26+1
A28: =A27+1 | G28: =G27+1 | M28: =M27+1
A29: =A28+1 | G29: =G28+1 | M29: =M28+1
A30: =A29+1 | G30: =G29+1 | M30: =M29+1
A31: =A30+1 | G31: =G30+1 | M31: =M30+1
A32: =A31+1 | G32: =G31+1 | M32: =M31+1
A33: =A32+1 | G33: =G32+1 | M33: =M32+1
A34: =A33+1 | G34: =G33+1 | M34: =M33+1
A35: =A34+1 | G35: =G34+1 | M35: =M34+1
... A47: =A46+1 | G47: =G46+1 | M47: =M46+1
A48: Toplam | G48: Toplam | M48: Toplam
A49: [S] Kalan | G49: [S] Kalan | M49: [S] Kalan
A50: [S] Faiz farkı | G50: [S] Faiz farkı | M50: [S] Faiz farkı
A53: G2 (12 dk): maliyet, sıralama ve bütçe kuralı
A54: Ay 0: ele geçen tutar (kredi - tahsis ücreti), artı. Ay 1..vade: taksit, eksi. Aylık maliyet bu akışın iç verim oranıdır; TCMB'nin oranı da aynı yolla hesaplanır (Karar sayfası, K1).
A55: Ay | B55: Teklif A akışı | C55: Teklif B akışı | D55: Teklif C akışı
...

Sheet Ileri
A1: İleri: çözümlü örnek ve görev (isteğe bağlı, evde tamamlanabilir)
A2: B sütunu çözümlü örnektir. C sütununda aynı hesap yeni girdilerle yapılır. D sütunu formülü ve açıklamasını gösterir.
A3: C sütunu elle yazılır: B'deki formül sağa sürüklenmez, kopyalanmaz. Sonuç B'deki kalıpla karşılaştırılır.
A4: İleri 1: taksitin kapalı formülü
B5: Çözümlü örnek | C5: Görev
A6: [G] Kredi tutarı | B6: 100000 | C6: 250000
A7: [G] Aylık faiz oranı | B7: 0.03 | C7: 0.025
A8: [G] Vade (ay) | B8: 12 | C8: 36
A9: [H] Taksit, elle formül | B9: =B6*B7/(1-(1+B7)^(-B8)) | D9: Formül: =B6*B7/(1-(1+B7)^(-B8)). Fonksiyon adı ve argüman ayracı içermediği için her Excel dilinde aynı yazılır. C9 elle, sürüklemeden yazılır.
A10: [H] Taksit, PMT | B10: =-PMT(B7,B8,B6) | D10: Formül: =-PMT(B7,B8,B6)
A11: [S] Fark | B11: =B9-B10 | D11: 0 çıkmalı. H7'de bu formül bir Python fonksiyonu olarak yazılır.
A13: İleri 2: tahsis ücretli kredinin aylık maliyeti (RATE)
B14: Çözümlü örnek | C14: Görev
A15: [G] Kredi tutarı (sözleşmede yazan) | B15: 100000 | C15: 150000
A16: [G] Akdi aylık faiz (ilan edilen oran) | B16: 0.03 | C16: 0.0279
A17: [G] Vade (ay) | B17: 12 | C17: 12
A18: [G] Tahsis ücreti (kredi verilirken peşin kesilen) | B18: 500 | C18: 750
A19: [H] Aylık taksit (sözleşme tutarı üzerinden) | B19: =-PMT(B16,B17,B15) | D19: Formül: =-PMT(B16,B17,B15). Taksit ücretten etkilenmez.
A20: [H] Ele geçen tutar | B20: =B15-B18
A21: [H] Aylık maliyet (ücret dahil) | B21: =RATE(B17,-B19,B20) | D21: Formül: =RATE(B17,-B19,B20): B20 kadar para alınıp B17 ay boyunca her ay B19 ödenirse aylık oran.
A22: [Y] Aylık maliyet - akdi aylık faiz (yüzde puan) | B22: =B21-B16 | D22: İki oranın farkı: hücre yüzde biçimli olduğu için yanında % görünür, ama okunuşu yüzde puandır (H2). Ücret akdi faizi değiştirmez, ama maliyeti artırır. Yıllık karşılığı, puana çevirme ve IRR ile sağlama: Finans sayfası, finans alıştırması.
A24: İleri 3: kaç ay sürer? (NPER)
B25: Çözümlü örnek: kredi | C25: Görev: birikim
A26: [G] Aylık faiz oranı | B26: 0.03 | C26: 0.025
A27: [G] Her ay ödenen ya da yatırılan tutar | B27: 7500 | C27: 2000
A28: [G] Bugün ele geçen tutar (pv) | B28: 100000 | C28: 0
A29: [G] Sonunda ele geçecek tutar (fv) | B29: 0 | C29: 50000
A30: [İ] İşaret | D30: Gelen para artı, çıkan para eksi: her ayki ödeme -B27; pv ve fv artı.
A31: [H] Dönem sayısı (ay) | B31: =NPER(B26,-B27,B28,B29) | D31: Formül: =NPER(B26,-B27,B28,B29). Sonuç tam sayı değilse tam taksitler yetmez; son ayda daha küçük bir ödeme gerekir.
A32: [Y] Yorum | D32: Aynı fonksiyon hem kredi hem birikim için çalışır; fark yalnız hangi girdinin 0 olduğundadır.
A33: [S] Sağlama: bulunan ay sayısıyla PV - pv | B33: =PV(B26,B31,-B27,B29)-B28 | D33: Formül: =PV(B26,B31,-B27,B29)-B28. Bulunan ay sayısını geri koyunca başlangıca dönülmeli, 0 çıkmalı.
A35: İleri 4: yıllık nominal ve etkin oran (EFFECT, NOMINAL)
B36: Çözümlü örnek | C36: Görev
A37: [G] Aylık faiz oranı | B37: 0.03 | C37: 0.0375
A38: [G] Yılda dönem sayısı | B38: 12 | C38: 12
A39: [H] Yıllık nominal oran | B39: =B37*B38 | D39: Aylık oran × yılda dönem sayısı (B38). Faizin faizi hesaba katılmaz.
A40: [H] Yıllık etkin oran | B40: =EFFECT(B39,B38) | D40: Formül: =EFFECT(B39,B38): faizin faizi dahil yıllık oran.
A41: [S] Sağlama: bileşik formül | B41: =(1+B37)^B38-1 | D41: H2'deki bileşik faiz: (1 + aylık oran) ^ yılda dönem sayısı (B38) - 1
A42: [S] Fark | B42: =B40-B41
A43: [H] Etkinden nominale geri | B43: =NOMINAL(B40,B38) | D43: Formül: =NOMINAL(B40,B38): baştaki nominal oran geri gelmeli.
...

Sheet Ev
A1: Ev çalışması (notsuz): 24 aylık taşıt kredisi
A2: Alıştırmadaki tablo bu kez 24 ay için kurulur. Varsayımlar öğretim amaçlıdır; gerçek bir banka teklifi değildir.
A3: Tüketici kredisinde faizin yanında %15 KKDF (faiz tutarı üzerinden) ve %15 BSMV (bankanın lehine aldığı paralar üzerinden; başlıcası faiz) ödenir; banka tahsis ücreti de alabilir (el kitabı f03, 4. bölüm). Bu dosya bunları içermez. Yasal kredi sınırları da dikkate alınmadı.
A4: [G] Varsayımlar
A5: Aracın fiyatı | B5: 900000
A6: Peşinat (cepten ödenen) | B6: 400000
A7: Aylık faiz oranı | B7: 0.0249
A8: Vade (ay) | B8: 24
A10: [H] Hesap
A11: Kredi tutarı
A12: Aylık taksit
A13: Toplam ödeme
A14: Toplam faiz
A15: Toplam maliyet (peşinat + ödemeler)
A17: Dönem | B17: Başlangıç borcu | C17: Faiz | D17: Anapara | E17: Taksit | F17: Kalan borç | G17: Sağlama: IPMT | H17: Fark
A18: 0 | F18: =B11
A19: =A18+1
A20: =A19+1
A21: =A20+1
A22: =A21+1
A23: =A22+1
A24: =A23+1
A25: =A24+1
A26: =A25+1
A27: =A26+1
A28: =A27+1
A29: =A28+1
A30: =A29+1
... A42: =A41+1
A43: Toplam
A45: [S] Son dönemde kalan borç (0 olmalı)
A46: [S] Tablodaki toplam faiz - B14
